Workbook

Sheet ▶ Cover (2)
B2: SE | D2: Schneider Electric
D3: APEX TOP 25 · Strategic Account Manager Assessment Tool
B5: 3 Assessment Lenses · 22 Capabilities ·
B8: SCORING FRAMEWORK
B9: L1 – Developing | D9: Behaviours absent or very inconsistent — significant development needed
B10: L2 – Proficient | D10: Consistently demonstrated — meets the required level for this account
B11: L3 – Advanced | D11: Benchmark quality — role model and reference for other APEX AMs
B13: THREE ASSESSMENT LENSES
B14: SELF | D14: Account Manager self-assessment — honest reflection of own capability level
B15: MANAGER | D15: Line manager assessment — direct observation and performance evidence
B16: APEX PANEL | D16: Unbiased panel — Global Account Managers & Global Segment Leaders
B18: INSTRUCTIONS
B19: 1. Please review the Capability Guide tab before starting the assessment.
B20: 2. For each capability, read the definitions and behavioural indicators for L1 (Developing), L2 (Proficient), and L3 (Advanced), and select the level that best reflects your current capability.
B21: 3. Complete the Self Assessment section based on an honest evaluation of your current performance and behaviours.
B22: 4. Where relevant, add comments or examples in the Notes section to support your assessment.

Sheet ▶ Capability Guide
B2: SE | D2: Schneider Electric
D3: CAPABILITY DEFINITIONS · L1 / L2 / L3 Behavioural Anchors
B5: Use these definitions to calibrate scores consistently across all three assessment lenses
B7: Capability | C7: Cluster | D7: Src | E7: Acq Req | F7: Sat Req | G7: L1 — Developing | H7: L2 — Proficient | I7: L3 — Advanced
B8: Account Management. | C8: Account Strategy & Planning | D8: SE | E8: L3 | F8: L3 | G8: Drafts or contributes to the account plan but relies on others for overall direction; priorities broad or reactive | H8: Leads a coherent Strategic Account Plan with clear priorities linked to ambition and growth plays; runs regular reviews | I8: Uses the account plan as a steering tool for the Virtual Team and sponsors; anticipates shifts and proactively repositions
B9: Strategic Account Ambition. | C9: Account Strategy & Planning | D9: C | E9: L2 | F9: L2 | G9: Describes ambition mainly as 'more business' without clear positioning or focus | H9: Defines Schneider's strategic intent, target position, and ambition for the account with a clear narrative | I9: Crafts an ambition that galvanizes sponsors and the Virtual Team; uses it to unlock bigger moves
B10: Consultative Selling. | C10: Commercial & Sales Excellence | D10: SE | E10: L2 | F10: L2 | G10: Leads with products/features; some discovery questions but weak link to business context | H10: Anchors discussions in customer priorities and pain points; links offers to clear business outcomes | I10: Reframes customer thinking and creates new space for Schneider; recognized as trusted advisor
B11: Negotiation. | C11: Commercial & Sales Excellence | D11: SE | E11: L2 | F11: L2 | G11: Focuses mainly on price and concessions; reacts to customer demands; escalates quickly | H11: Adapts negotiation approach to account context, risk, and strategic importance; prepares options | I11: Designs and leads negotiation strategies that strengthen strategic position; helps others prepare
B12: Value Creation / Business Case. | C12: Commercial & Sales Excellence | D12: C | E12: L2 | F12: L2 | G12: Talks about benefits in broad terms; business case elements are incomplete or generic | H12: Builds solid value arguments with data or credible logic; tailors the case to different stakeholders | I12: Uses value logic to reshape scope, structure, or commercial model; reference for strong value cases
B13: Customer Relationship Management. | C13: Executive & Customer Leadership | D13: SE | E13: L2 | F13: L2 | G13: Has working relationships around active deals but limited depth; depends on others to open doors | H13: Maintains a healthy network across functions and levels; spots relationship risks and works to rebalance | I13: Is perceived as a trusted interface to Schneider; manages complex stakeholder dynamics constructively
B14: Stakeholder Management. | C14: Executive & Customer Leadership | D14: SE | E14: L2 | F14: L2 | G14: Sees stakeholders mainly through deal contacts; mapping incomplete or not kept current | H14: Maintains a clear stakeholder map; actively works to align key players around priorities and actions | I14: Anticipates shifts in influence and politics; orchestrates alignment across difficult coalitions
B15: Influencing Skills. | C15: Executive & Customer Leadership | D15: SE | E15: L2 | F15: L2 | G15: Escalates quickly when facing resistance; tends to push messages rather than adapt | H15: Adjusts style to audience; builds coalitions and uses facts, value, and relationships to secure alignment | I15: Influences high-stakes decisions with senior stakeholders; regularly unblocks stuck topics
B16: Executive Presence | C16: Executive & Customer Leadership | D16: C | E16: L2 | F16: L2 | G16: Feels less at ease in executive forums; messages can be too detailed or unclear | H16: Prepares and delivers clear, concise messages at executive level; represents Schneider confidently | I16: Shapes executive conversations and positions Schneider as strategic partner; trusted in C-suite
B17: C-Level Engagement. | C17: Executive & Customer Leadership | D17: C | E17: L2 | F17: L2 | G17: Participates in senior meetings mainly as observer; limited link to customer enterprise agenda | H17: Plans and leads targeted C-level interactions connected to account ambition | I17: Uses C-level interactions to open new spaces for Schneider and accelerate key decisions
B18: Executive Sponsorship Mobilization. | C18: Executive & Customer Leadership | D18: C | E18: L2 | F18: L2 | G18: Involves sponsors occasionally without clear objectives or preparation | H18: Plans sponsor involvement with clear objectives; briefs and debriefs sponsors systematically | I18: Strategically sequences sponsor involvement to unlock new plays and de-block issues
... B29: Software & Services Attach. | C29: Saturation Excellence | D29: S | E29: — | F29: L2 | G29: Mentions software/services occasionally but not systematically | H29: Identifies and positions software, digital, and services offers on top of core business footprint | I29: Embeds attach logic into how the account is run; drives meaningful growth in software/services mix

Sheet Employee 1
B2: SE | D2: Schneider Electric
D3: APEX ASSESSMENT · AM01
B5: Account Manager: Account Manager 1 · Account: Account 1 · Zone: MEA · Track: Acquisition
B7: Account Manager | D7: Account Manager 1 | E7: Account Name | G7: Account 1 | H7: Zone | I7: MEA | J7: Track | K7: Acquisition
B8: Self Assessment Date: | E8: Manager Assessment Date: | H8: APEX Panel Date:
E9: ◀ SELF ASSESSMENT ▶ | F9: ◀ MANAGER ASSESSMENT ▶ | G9: ◀ APEX PANEL ASSESSMENT ▶
B10: Capability | C10: Src | D10: Req Lv | E10: SELF (L1/L2/L3) | F10: MANAGER (L1/L2/L3) | G10: APEX PANEL (L1/L2/L3) | H10: Self # | I10: Mgr # | J10: APEX # | K10: Notes / Evidence & Behavioural Observations | M10: Capability | N10: Self | O10: Manager | P10: APEX | Q10: Target
B11: Account Management | C11: SE | D11: L3 | H11: =IF(E11="L3 - Advanced",3,IF(E11="L2 - Proficient",2,IF(E11="L1 - Developing",1,""))) | I11: =IF(F11="L3 - Advanced",3,IF(F11="L2 - Proficient",2,IF(F11="L1 - Developing",1,""))) | J11: =IF(G11="L3 - Advanced",3,IF(G11="L2 - Proficient",2,IF(G11="L1 - Developing",1,""))) | M11: Acct Mgmt | N11: =H11 | O11: =I11 | P11: =J11 | Q11: 2
B12: Strategic Account Ambition | C12: C | D12: L2 | H12: =IF(E12="L3 - Advanced",3,IF(E12="L2 - Proficient",2,IF(E12="L1 - Developing",1,""))) | I12: =IF(F12="L3 - Advanced",3,IF(F12="L2 - Proficient",2,IF(F12="L1 - Developing",1,""))) | J12: =IF(G12="L3 - Advanced",3,IF(G12="L2 - Proficient",2,IF(G12="L1 - Developing",1,""))) | M12: Strat Ambition | N12: =H12 | O12: =I12 | P12: =J12 | Q12: 2
B13: Consultative Selling | C13: SE | D13: L2 | H13: =IF(E13="L3 - Advanced",3,IF(E13="L2 - Proficient",2,IF(E13="L1 - Developing",1,""))) | I13: =IF(F13="L3 - Advanced",3,IF(F13="L2 - Proficient",2,IF(F13="L1 - Developing",1,""))) | J13: =IF(G13="L3 - Advanced",3,IF(G13="L2 - Proficient",2,IF(G13="L1 - Developing",1,""))) | M13: Consultative | N13: =H13 | O13: =I13 | P13: =J13 | Q13: 2
B14: Negotiation | C14: SE | D14: L2 | H14: =IF(E14="L3 - Advanced",3,IF(E14="L2 - Proficient",2,IF(E14="L1 - Developing",1,""))) | I14: =IF(F14="L3 - Advanced",3,IF(F14="L2 - Proficient",2,IF(F14="L1 - Developing",1,""))) | J14: =IF(G14="L3 - Advanced",3,IF(G14="L2 - Proficient",2,IF(G14="L1 - Developing",1,""))) | M14: Negotiation | N14: =H14 | O14: =I14 | P14: =J14 | Q14: 2
B15: Value Creation / Business Case | C15: C | D15: L2 | H15: =IF(E15="L3 - Advanced",3,IF(E15="L2 - Proficient",2,IF(E15="L1 - Developing",1,""))) | I15: =IF(F15="L3 - Advanced",3,IF(F15="L2 - Proficient",2,IF(F15="L1 - Developing",1,""))) | J15: =IF(G15="L3 - Advanced",3,IF(G15="L2 - Proficient",2,IF(G15="L1 - Developing",1,""))) | M15: Value/BizCase | N15: =H15 | O15: =I15 | P15: =J15 | Q15: 2
B16: Customer Relationship Management | C16: SE | D16: L2 | H16: =IF(E16="L3 - Advanced",3,IF(E16="L2 - Proficient",2,IF(E16="L1 - Developing",1,""))) | I16: =IF(F16="L3 - Advanced",3,IF(F16="L2 - Proficient",2,IF(F16="L1 - Developing",1,""))) | J16: =IF(G16="L3 - Advanced",3,IF(G16="L2 - Proficient",2,IF(G16="L1 - Developing",1,""))) | M16: CRM | N16: =H16 | O16: =I16 | P16: =J16 | Q16: 2
B17: Stakeholder Management | C17: SE | D17: L2 | H17: =IF(E17="L3 - Advanced",3,IF(E17="L2 - Proficient",2,IF(E17="L1 - Developing",1,""))) | I17: =IF(F17="L3 - Advanced",3,IF(F17="L2 - Proficient",2,IF(F17="L1 - Developing",1,""))) | J17: =IF(G17="L3 - Advanced",3,IF(G17="L2 - Proficient",2,IF(G17="L1 - Developing",1,""))) | M17: Stakeholder | N17: =H17 | O17: =I17 | P17: =J17 | Q17: 2
B18: Influencing Skills | C18: SE | D18: L2 | H18: =IF(E18="L3 - Advanced",3,IF(E18="L2 - Proficient",2,IF(E18="L1 - Developing",1,""))) | I18: =IF(F18="L3 - Advanced",3,IF(F18="L2 - Proficient",2,IF(F18="L1 - Developing",1,""))) | J18: =IF(G18="L3 - Advanced",3,IF(G18="L2 - Proficient",2,IF(G18="L1 - Developing",1,""))) | M18: Influencing | N18: =H18 | O18: =I18 | P18: =J18 | Q18: 2
B19: Executive Presence | C19: C | D19: L2 | H19: =IF(E19="L3 - Advanced",3,IF(E19="L2 - Proficient",2,IF(E19="L1 - Developing",1,""))) | I19: =IF(F19="L3 - Advanced",3,IF(F19="L2 - Proficient",2,IF(F19="L1 - Developing",1,""))) | J19: =IF(G19="L3 - Advanced",3,IF(G19="L2 - Proficient",2,IF(G19="L1 - Developing",1,""))) | M19: Exec Presence | N19: =H19 | O19: =I19 | P19: =J19 | Q19: 2
B20: C-Level Engagement | C20: C | D20: L2 | H20: =IF(E20="L3 - Advanced",3,IF(E20="L2 - Proficient",2,IF(E20="L1 - Developing",1,""))) | I20: =IF(F20="L3 - Advanced",3,IF(F20="L2 - Proficient",2,IF(F20="L1 - Developing",1,""))) | J20: =IF(G20="L3 - Advanced",3,IF(G20="L2 - Proficient",2,IF(G20="L1 - Developing",1,""))) | M20: C-Level | N20: =H20 | O20: =I20 | P20: =J20 | Q20: 2
B21: Executive Sponsorship Mobilization | C21: C | D21: L2 | H21: =IF(E21="L3 - Advanced",3,IF(E21="L2 - Proficient",2,IF(E21="L1 - Developing",1,""))) | I21: =IF(F21="L3 - Advanced",3,IF(F21="L2 - Proficient",2,IF(F21="L1 - Developing",1,""))) | J21: =IF(G21="L3 - Advanced",3,IF(G21="L2 - Proficient",2,IF(G21="L1 - Developing",1,""))) | M21: Exec Sponsor | N21: =H21 | O21: =I21 | P21: =J21 | Q21: 2
B22: Product Knowledge | C22: SE | D22: L2 | H22: =IF(E22="L3 - Advanced",3,IF(E22="L2 - Proficient",2,IF(E22="L1 - Developing",1,""))) | I22: =IF(F22="L3 - Advanced",3,IF(F22="L2 - Proficient",2,IF(F22="L1 - Developing",1,""))) | J22: =IF(G22="L3 - Advanced",3,IF(G22="L2 - Proficient",2,IF(G22="L1 - Developing",1,""))) | M22: Product Know | N22: =H22 | O22: =I22 | P22: =J22 | Q22: 2
... B32: Software & Services Attach | C32: S | D32: L2 | H32: =IF(E32="L3 - Advanced",3,IF(E32="L2 - Proficient",2,IF(E32="L1 - Developing",1,""))) | I32: =IF(F32="L3 - Advanced",3,IF(F32="L2 - Proficient",2,IF(F32="L1 - Developing",1,""))) | J32: =IF(G32="L3 - Advanced",3,IF(G32="L2 - Proficient",2,IF(G32="L1 - Developing",1,""))) | M32: SW/Svc Attach | N32: =H32 | O32: =I32 | P32: =J32 | Q32: 2
B33: AVERAGE MATURITY SCORE | E33: =IFERROR(AVERAGE(H11:H32),"") | F33: =IFERROR(AVERAGE(I11:I32),"") | G33: =IFERROR(AVERAGE(J11:J32),"") | H33: =IFERROR(AVERAGE(H11:J32),"")

Sheet Mohamed MARZOUK
B2: SE | D2: Schneider Electric
D3: APEX ASSESSMENT · AM02
B5: Account Manager: Account Manager 2 · Account: Account 2 · Zone: MEA · Track: Saturation
B7: Account Manager | D7: Account Manager 2 | E7: Account Name | G7: Account 2 | H7: Zone | I7: MEA | J7: Track | K7: Saturation
B8: Self Assessment Date: | E8: Manager Assessment Date: | H8: APEX Panel Date:
E9: ◀ SELF ASSESSMENT ▶ | F9: ◀ MANAGER ASSESSMENT ▶ | G9: ◀ APEX PANEL ASSESSMENT ▶
B10: Capability | C10: Src | D10: Req Lv | E10: SELF (L1/L2/L3) | F10: MANAGER (L1/L2/L3) | G10: APEX PANEL (L1/L2/L3) | H10: Self # | I10: Mgr # | J10: APEX # | K10: Notes / Evidence & Behavioural Observations | M10: Capability | N10: Self | O10: Manager | P10: APEX | Q10: Target
B11: Account Management | C11: SE | D11: L3 | H11: =IF(E11="L3 - Advanced",3,IF(E11="L2 - Proficient",2,IF(E11="L1 - Developing",1,""))) | I11: =IF(F11="L3 - Advanced",3,IF(F11="L2 - Proficient",2,IF(F11="L1 - Developing",1,""))) | J11: =IF(G11="L3 - Advanced",3,IF(G11="L2 - Proficient",2,IF(G11="L1 - Developing",1,""))) | M11: Acct Mgmt | N11: =H11 | O11: =I11 | P11: =J11 | Q11: 2
B12: Strategic Account Ambition | C12: C | D12: L2 | H12: =IF(E12="L3 - Advanced",3,IF(E12="L2 - Proficient",2,IF(E12="L1 - Developing",1,""))) | I12: =IF(F12="L3 - Advanced",3,IF(F12="L2 - Proficient",2,IF(F12="L1 - Developing",1,""))) | J12: =IF(G12="L3 - Advanced",3,IF(G12="L2 - Proficient",2,IF(G12="L1 - Developing",1,""))) | M12: Strat Ambition | N12: =H12 | O12: =I12 | P12: =J12 | Q12: 2
B13: Consultative Selling | C13: SE | D13: L2 | H13: =IF(E13="L3 - Advanced",3,IF(E13="L2 - Proficient",2,IF(E13="L1 - Developing",1,""))) | I13: =IF(F13="L3 - Advanced",3,IF(F13="L2 - Proficient",2,IF(F13="L1 - Developing",1,""))) | J13: =IF(G13="L3 - Advanced",3,IF(G13="L2 - Proficient",2,IF(G13="L1 - Developing",1,""))) | M13: Consultative | N13: =H13 | O13: =I13 | P13: =J13 | Q13: 2
B14: Negotiation | C14: SE | D14: L2 | H14: =IF(E14="L3 - Advanced",3,IF(E14="L2 - Proficient",2,IF(E14="L1 - Developing",1,""))) | I14: =IF(F14="L3 - Advanced",3,IF(F14="L2 - Proficient",2,IF(F14="L1 - Developing",1,""))) | J14: =IF(G14="L3 - Advanced",3,IF(G14="L2 - Proficient",2,IF(G14="L1 - Developing",1,""))) | M14: Negotiation | N14: =H14 | O14: =I14 | P14: =J14 | Q14: 2
B15: Value Creation / Business Case | C15: C | D15: L2 | H15: =IF(E15="L3 - Advanced",3,IF(E15="L2 - Proficient",2,IF(E15="L1 - Developing",1,""))) | I15: =IF(F15="L3 - Advanced",3,IF(F15="L2 - Proficient",2,IF(F15="L1 - Developing",1,""))) | J15: =IF(G15="L3 - Advanced",3,IF(G15="L2 - Proficient",2,IF(G15="L1 - Developing",1,""))) | M15: Value/BizCase | N15: =H15 | O15: =I15 | P15: =J15 | Q15: 2
B16: Customer Relationship Management | C16: SE | D16: L2 | H16: =IF(E16="L3 - Advanced",3,IF(E16="L2 - Proficient",2,IF(E16="L1 - Developing",1,""))) | I16: =IF(F16="L3 - Advanced",3,IF(F16="L2 - Proficient",2,IF(F16="L1 - Developing",1,""))) | J16: =IF(G16="L3 - Advanced",3,IF(G16="L2 - Proficient",2,IF(G16="L1 - Developing",1,""))) | M16: CRM | N16: =H16 | O16: =I16 | P16: =J16 | Q16: 2
B17: Stakeholder Management | C17: SE | D17: L2 | H17: =IF(E17="L3 - Advanced",3,IF(E17="L2 - Proficient",2,IF(E17="L1 - Developing",1,""))) | I17: =IF(F17="L3 - Advanced",3,IF(F17="L2 - Proficient",2,IF(F17="L1 - Developing",1,""))) | J17: =IF(G17="L3 - Advanced",3,IF(G17="L2 - Proficient",2,IF(G17="L1 - Developing",1,""))) | M17: Stakeholder | N17: =H17 | O17: =I17 | P17: =J17 | Q17: 2
B18: Influencing Skills | C18: SE | D18: L2 | H18: =IF(E18="L3 - Advanced",3,IF(E18="L2 - Proficient",2,IF(E18="L1 - Developing",1,""))) | I18: =IF(F18="L3 - Advanced",3,IF(F18="L2 - Proficient",2,IF(F18="L1 - Developing",1,""))) | J18: =IF(G18="L3 - Advanced",3,IF(G18="L2 - Proficient",2,IF(G18="L1 - Developing",1,""))) | M18: Influencing | N18: =H18 | O18: =I18 | P18: =J18 | Q18: 2
B19: Executive Presence | C19: C | D19: L2 | H19: =IF(E19="L3 - Advanced",3,IF(E19="L2 - Proficient",2,IF(E19="L1 - Developing",1,""))) | I19: =IF(F19="L3 - Advanced",3,IF(F19="L2 - Proficient",2,IF(F19="L1 - Developing",1,""))) | J19: =IF(G19="L3 - Advanced",3,IF(G19="L2 - Proficient",2,IF(G19="L1 - Developing",1,""))) | M19: Exec Presence | N19: =H19 | O19: =I19 | P19: =J19 | Q19: 2
B20: C-Level Engagement | C20: C | D20: L2 | H20: =IF(E20="L3 - Advanced",3,IF(E20="L2 - Proficient",2,IF(E20="L1 - Developing",1,""))) | I20: =IF(F20="L3 - Advanced",3,IF(F20="L2 - Proficient",2,IF(F20="L1 - Developing",1,""))) | J20: =IF(G20="L3 - Advanced",3,IF(G20="L2 - Proficient",2,IF(G20="L1 - Developing",1,""))) | M20: C-Level | N20: =H20 | O20: =I20 | P20: =J20 | Q20: 2
B21: Executive Sponsorship Mobilization | C21: C | D21: L2 | H21: =IF(E21="L3 - Advanced",3,IF(E21="L2 - Proficient",2,IF(E21="L1 - Developing",1,""))) | I21: =IF(F21="L3 - Advanced",3,IF(F21="L2 - Proficient",2,IF(F21="L1 - Developing",1,""))) | J21: =IF(G21="L3 - Advanced",3,IF(G21="L2 - Proficient",2,IF(G21="L1 - Developing",1,""))) | M21: Exec Sponsor | N21: =H21 | O21: =I21 | P21: =J21 | Q21: 2
B22: Product Knowledge | C22: SE | D22: L2 | H22: =IF(E22="L3 - Advanced",3,IF(E22="L2 - Proficient",2,IF(E22="L1 - Developing",1,""))) | I22: =IF(F22="L3 - Advanced",3,IF(F22="L2 - Proficient",2,IF(F22="L1 - Developing",1,""))) | J22: =IF(G22="L3 - Advanced",3,IF(G22="L2 - Proficient",2,IF(G22="L1 - Developing",1,""))) | M22: Product Know | N22: =H22 | O22: =I22 | P22: =J22 | Q22: 2
... B32: Software & Services Attach | C32: S | D32: L2 | H32: =IF(E32="L3 - Advanced",3,IF(E32="L2 - Proficient",2,IF(E32="L1 - Developing",1,""))) | I32: =IF(F32="L3 - Advanced",3,IF(F32="L2 - Proficient",2,IF(F32="L1 - Developing",1,""))) | J32: =IF(G32="L3 - Advanced",3,IF(G32="L2 - Proficient",2,IF(G32="L1 - Developing",1,""))) | M32: SW/Svc Attach | N32: =H32 | O32: =I32 | P32: =J32 | Q32: 2
B33: AVERAGE MATURITY SCORE | E33: =IFERROR(AVERAGE(H11:H32),"") | F33: =IFERROR(AVERAGE(I11:I32),"") | G33: =IFERROR(AVERAGE(J11:J32),"") | H33: =IFERROR(AVERAGE(H11:J32),"")

Sheet Basim El-Subihy
B2: SE | D2: Schneider Electric
D3: APEX ASSESSMENT · AM03
B5: Account Manager: Account Manager 3 · Account: Account 3 · Zone: MEA · Track: Acquisition
B7: Account Manager | D7: Account Manager 3 | E7: Account Name | G7: Account 3 | H7: Zone | I7: MEA | J7: Track | K7: Acquisition
B8: Self Assessment Date: | E8: Manager Assessment Date: | H8: APEX Panel Date:
E9: ◀ SELF ASSESSMENT ▶ | F9: ◀ MANAGER ASSESSMENT ▶ | G9: ◀ APEX PANEL ASSESSMENT ▶
B10: Capability | C10: Src | D10: Req Lv | E10: SELF (L1/L2/L3) | F10: MANAGER (L1/L2/L3) | G10: APEX PANEL (L1/L2/L3) | H10: Self # | I10: Mgr # | J10: APEX # | K10: Notes / Evidence & Behavioural Observations | M10: Capability | N10: Self | O10: Manager | P10: APEX | Q10: Target
B11: Account Management | C11: SE | D11: L3 | H11: =IF(E11="L3 - Advanced",3,IF(E11="L2 - Proficient",2,IF(E11="L1 - Developing",1,""))) | I11: =IF(F11="L3 - Advanced",3,IF(F11="L2 - Proficient",2,IF(F11="L1 - Developing",1,""))) | J11: =IF(G11="L3 - Advanced",3,IF(G11="L2 - Proficient",2,IF(G11="L1 - Developing",1,""))) | M11: Acct Mgmt | N11: =H11 | O11: =I11 | P11: =J11 | Q11: 2
B12: Strategic Account Ambition | C12: C | D12: L2 | H12: =IF(E12="L3 - Advanced",3,IF(E12="L2 - Proficient",2,IF(E12="L1 - Developing",1,""))) | I12: =IF(F12="L3 - Advanced",3,IF(F12="L2 - Proficient",2,IF(F12="L1 - Developing",1,""))) | J12: =IF(G12="L3 - Advanced",3,IF(G12="L2 - Proficient",2,IF(G12="L1 - Developing",1,""))) | M12: Strat Ambition | N12: =H12 | O12: =I12 | P12: =J12 | Q12: 2
B13: Consultative Selling | C13: SE | D13: L2 | H13: =IF(E13="L3 - Advanced",3,IF(E13="L2 - Proficient",2,IF(E13="L1 - Developing",1,""))) | I13: =IF(F13="L3 - Advanced",3,IF(F13="L2 - Proficient",2,IF(F13="L1 - Developing",1,""))) | J13: =IF(G13="L3 - Advanced",3,IF(G13="L2 - Proficient",2,IF(G13="L1 - Developing",1,""))) | M13: Consultative | N13: =H13 | O13: =I13 | P13: =J13 | Q13: 2
B14: Negotiation | C14: SE | D14: L2 | H14: =IF(E14="L3 - Advanced",3,IF(E14="L2 - Proficient",2,IF(E14="L1 - Developing",1,""))) | I14: =IF(F14="L3 - Advanced",3,IF(F14="L2 - Proficient",2,IF(F14="L1 - Developing",1,""))) | J14: =IF(G14="L3 - Advanced",3,IF(G14="L2 - Proficient",2,IF(G14="L1 - Developing",1,""))) | M14: Negotiation | N14: =H14 | O14: =I14 | P14: =J14 | Q14: 2
B15: Value Creation / Business Case | C15: C | D15: L2 | H15: =IF(E15="L3 - Advanced",3,IF(E15="L2 - Proficient",2,IF(E15="L1 - Developing",1,""))) | I15: =IF(F15="L3 - Advanced",3,IF(F15="L2 - Proficient",2,IF(F15="L1 - Developing",1,""))) | J15: =IF(G15="L3 - Advanced",3,IF(G15="L2 - Proficient",2,IF(G15="L1 - Developing",1,""))) | M15: Value/BizCase | N15: =H15 | O15: =I15 | P15: =J15 | Q15: 2
B16: Customer Relationship Management | C16: SE | D16: L2 | H16: =IF(E16="L3 - Advanced",3,IF(E16="L2 - Proficient",2,IF(E16="L1 - Developing",1,""))) | I16: =IF(F16="L3 - Advanced",3,IF(F16="L2 - Proficient",2,IF(F16="L1 - Developing",1,""))) | J16: =IF(G16="L3 - Advanced",3,IF(G16="L2 - Proficient",2,IF(G16="L1 - Developing",1,""))) | M16: CRM | N16: =H16 | O16: =I16 | P16: =J16 | Q16: 2
B17: Stakeholder Management | C17: SE | D17: L2 | H17: =IF(E17="L3 - Advanced",3,IF(E17="L2 - Proficient",2,IF(E17="L1 - Developing",1,""))) | I17: =IF(F17="L3 - Advanced",3,IF(F17="L2 - Proficient",2,IF(F17="L1 - Developing",1,""))) | J17: =IF(G17="L3 - Advanced",3,IF(G17="L2 - Proficient",2,IF(G17="L1 - Developing",1,""))) | M17: Stakeholder | N17: =H17 | O17: =I17 | P17: =J17 | Q17: 2
B18: Influencing Skills | C18: SE | D18: L2 | H18: =IF(E18="L3 - Advanced",3,IF(E18="L2 - Proficient",2,IF(E18="L1 - Developing",1,""))) | I18: =IF(F18="L3 - Advanced",3,IF(F18="L2 - Proficient",2,IF(F18="L1 - Developing",1,""))) | J18: =IF(G18="L3 - Advanced",3,IF(G18="L2 - Proficient",2,IF(G18="L1 - Developing",1,""))) | M18: Influencing | N18: =H18 | O18: =I18 | P18: =J18 | Q18: 2
B19: Executive Presence | C19: C | D19: L2 | H19: =IF(E19="L3 - Advanced",3,IF(E19="L2 - Proficient",2,IF(E19="L1 - Developing",1,""))) | I19: =IF(F19="L3 - Advanced",3,IF(F19="L2 - Proficient",2,IF(F19="L1 - Developing",1,""))) | J19: =IF(G19="L3 - Advanced",3,IF(G19="L2 - Proficient",2,IF(G19="L1 - Developing",1,""))) | M19: Exec Presence | N19: =H19 | O19: =I19 | P19: =J19 | Q19: 2
B20: C-Level Engagement | C20: C | D20: L2 | H20: =IF(E20="L3 - Advanced",3,IF(E20="L2 - Proficient",2,IF(E20="L1 - Developing",1,""))) | I20: =IF(F20="L3 - Advanced",3,IF(F20="L2 - Proficient",2,IF(F20="L1 - Developing",1,""))) | J20: =IF(G20="L3 - Advanced",3,IF(G20="L2 - Proficient",2,IF(G20="L1 - Developing",1,""))) | M20: C-Level | N20: =H20 | O20: =I20 | P20: =J20 | Q20: 2
B21: Executive Sponsorship Mobilization | C21: C | D21: L2 | H21: =IF(E21="L3 - Advanced",3,IF(E21="L2 - Proficient",2,IF(E21="L1 - Developing",1,""))) | I21: =IF(F21="L3 - Advanced",3,IF(F21="L2 - Proficient",2,IF(F21="L1 - Developing",1,""))) | J21: =IF(G21="L3 - Advanced",3,IF(G21="L2 - Proficient",2,IF(G21="L1 - Developing",1,""))) | M21: Exec Sponsor | N21: =H21 | O21: =I21 | P21: =J21 | Q21: 2
B22: Product Knowledge | C22: SE | D22: L2 | H22: =IF(E22="L3 - Advanced",3,IF(E22="L2 - Proficient",2,IF(E22="L1 - Developing",1,""))) | I22: =IF(F22="L3 - Advanced",3,IF(F22="L2 - Proficient",2,IF(F22="L1 - Developing",1,""))) | J22: =IF(G22="L3 - Advanced",3,IF(G22="L2 - Proficient",2,IF(G22="L1 - Developing",1,""))) | M22: Product Know | N22: =H22 | O22: =I22 | P22: =J22 | Q22: 2
... B32: Software & Services Attach | C32: S | D32: L2 | H32: =IF(E32="L3 - Advanced",3,IF(E32="L2 - Proficient",2,IF(E32="L1 - Developing",1,""))) | I32: =IF(F32="L3 - Advanced",3,IF(F32="L2 - Proficient",2,IF(F32="L1 - Developing",1,""))) | J32: =IF(G32="L3 - Advanced",3,IF(G32="L2 - Proficient",2,IF(G32="L1 - Developing",1,""))) | M32: SW/Svc Attach | N32: =H32 | O32: =I32 | P32: =J32 | Q32: 2
B33: AVERAGE MATURITY SCORE | E33: =IFERROR(AVERAGE(H11:H32),"") | F33: =IFERROR(AVERAGE(I11:I32),"") | G33: =IFERROR(AVERAGE(J11:J32),"") | H33: =IFERROR(AVERAGE(H11:J32),"")

Sheet Biju Mathew
B2: SE | D2: Schneider Electric
D3: APEX ASSESSMENT · AM04
B5: Account Manager: Account Manager 4 · Account: Account 4 · Zone: MEA · Track: Saturation
B7: Account Manager | D7: Account Manager 4 | E7: Account Name | G7: Account 4 | H7: Zone | I7: MEA | J7: Track | K7: Saturation
B8: Self Assessment Date: | E8: Manager Assessment Date: | H8: APEX Panel Date:
E9: ◀ SELF ASSESSMENT ▶ | F9: ◀ MANAGER ASSESSMENT ▶ | G9: ◀ APEX PANEL ASSESSMENT ▶
B10: Capability | C10: Src | D10: Req Lv | E10: SELF (L1/L2/L3) | F10: MANAGER (L1/L2/L3) | G10: APEX PANEL (L1/L2/L3) | H10: Self # | I10: Mgr # | J10: APEX # | K10: Notes / Evidence & Behavioural Observations | M10: Capability | N10: Self | O10: Manager | P10: APEX | Q10: Target
B11: Account Management | C11: SE | D11: L3 | H11: =IF(E11="L3 - Advanced",3,IF(E11="L2 - Proficient",2,IF(E11="L1 - Developing",1,""))) | I11: =IF(F11="L3 - Advanced",3,IF(F11="L2 - Proficient",2,IF(F11="L1 - Developing",1,""))) | J11: =IF(G11="L3 - Advanced",3,IF(G11="L2 - Proficient",2,IF(G11="L1 - Developing",1,""))) | M11: Acct Mgmt | N11: =H11 | O11: =I11 | P11: =J11 | Q11: 2
B12: Strategic Account Ambition | C12: C | D12: L2 | H12: =IF(E12="L3 - Advanced",3,IF(E12="L2 - Proficient",2,IF(E12="L1 - Developing",1,""))) | I12: =IF(F12="L3 - Advanced",3,IF(F12="L2 - Proficient",2,IF(F12="L1 - Developing",1,""))) | J12: =IF(G12="L3 - Advanced",3,IF(G12="L2 - Proficient",2,IF(G12="L1 - Developing",1,""))) | M12: Strat Ambition | N12: =H12 | O12: =I12 | P12: =J12 | Q12: 2
B13: Consultative Selling | C13: SE | D13: L2 | H13: =IF(E13="L3 - Advanced",3,IF(E13="L2 - Proficient",2,IF(E13="L1 - Developing",1,""))) | I13: =IF(F13="L3 - Advanced",3,IF(F13="L2 - Proficient",2,IF(F13="L1 - Developing",1,""))) | J13: =IF(G13="L3 - Advanced",3,IF(G13="L2 - Proficient",2,IF(G13="L1 - Developing",1,""))) | M13: Consultative | N13: =H13 | O13: =I13 | P13: =J13 | Q13: 2
B14: Negotiation | C14: SE | D14: L2 | H14: =IF(E14="L3 - Advanced",3,IF(E14="L2 - Proficient",2,IF(E14="L1 - Developing",1,""))) | I14: =IF(F14="L3 - Advanced",3,IF(F14="L2 - Proficient",2,IF(F14="L1 - Developing",1,""))) | J14: =IF(G14="L3 - Advanced",3,IF(G14="L2 - Proficient",2,IF(G14="L1 - Developing",1,""))) | M14: Negotiation | N14: =H14 | O14: =I14 | P14: =J14 | Q14: 2
B15: Value Creation / Business Case | C15: C | D15: L2 | H15: =IF(E15="L3 - Advanced",3,IF(E15="L2 - Proficient",2,IF(E15="L1 - Developing",1,""))) | I15: =IF(F15="L3 - Advanced",3,IF(F15="L2 - Proficient",2,IF(F15="L1 - Developing",1,""))) | J15: =IF(G15="L3 - Advanced",3,IF(G15="L2 - Proficient",2,IF(G15="L1 - Developing",1,""))) | M15: Value/BizCase | N15: =H15 | O15: =I15 | P15: =J15 | Q15: 2
B16: Customer Relationship Management | C16: SE | D16: L2 | H16: =IF(E16="L3 - Advanced",3,IF(E16="L2 - Proficient",2,IF(E16="L1 - Developing",1,""))) | I16: =IF(F16="L3 - Advanced",3,IF(F16="L2 - Proficient",2,IF(F16="L1 - Developing",1,""))) | J16: =IF(G16="L3 - Advanced",3,IF(G16="L2 - Proficient",2,IF(G16="L1 - Developing",1,""))) | M16: CRM | N16: =H16 | O16: =I16 | P16: =J16 | Q16: 2
B17: Stakeholder Management | C17: SE | D17: L2 | H17: =IF(E17="L3 - Advanced",3,IF(E17="L2 - Proficient",2,IF(E17="L1 - Developing",1,""))) | I17: =IF(F17="L3 - Advanced",3,IF(F17="L2 - Proficient",2,IF(F17="L1 - Developing",1,""))) | J17: =IF(G17="L3 - Advanced",3,IF(G17="L2 - Proficient",2,IF(G17="L1 - Developing",1,""))) | M17: Stakeholder | N17: =H17 | O17: =I17 | P17: =J17 | Q17: 2
B18: Influencing Skills | C18: SE | D18: L2 | H18: =IF(E18="L3 - Advanced",3,IF(E18="L2 - Proficient",2,IF(E18="L1 - Developing",1,""))) | I18: =IF(F18="L3 - Advanced",3,IF(F18="L2 - Proficient",2,IF(F18="L1 - Developing",1,""))) | J18: =IF(G18="L3 - Advanced",3,IF(G18="L2 - Proficient",2,IF(G18="L1 - Developing",1,""))) | M18: Influencing | N18: =H18 | O18: =I18 | P18: =J18 | Q18: 2
B19: Executive Presence | C19: C | D19: L2 | H19: =IF(E19="L3 - Advanced",3,IF(E19="L2 - Proficient",2,IF(E19="L1 - Developing",1,""))) | I19: =IF(F19="L3 - Advanced",3,IF(F19="L2 - Proficient",2,IF(F19="L1 - Developing",1,""))) | J19: =IF(G19="L3 - Advanced",3,IF(G19="L2 - Proficient",2,IF(G19="L1 - Developing",1,""))) | M19: Exec Presence | N19: =H19 | O19: =I19 | P19: =J19 | Q19: 2
B20: C-Level Engagement | C20: C | D20: L2 | H20: =IF(E20="L3 - Advanced",3,IF(E20="L2 - Proficient",2,IF(E20="L1 - Developing",1,""))) | I20: =IF(F20="L3 - Advanced",3,IF(F20="L2 - Proficient",2,IF(F20="L1 - Developing",1,""))) | J20: =IF(G20="L3 - Advanced",3,IF(G20="L2 - Proficient",2,IF(G20="L1 - Developing",1,""))) | M20: C-Level | N20: =H20 | O20: =I20 | P20: =J20 | Q20: 2
B21: Executive Sponsorship Mobilization | C21: C | D21: L2 | H21: =IF(E21="L3 - Advanced",3,IF(E21="L2 - Proficient",2,IF(E21="L1 - Developing",1,""))) | I21: =IF(F21="L3 - Advanced",3,IF(F21="L2 - Proficient",2,IF(F21="L1 - Developing",1,""))) | J21: =IF(G21="L3 - Advanced",3,IF(G21="L2 - Proficient",2,IF(G21="L1 - Developing",1,""))) | M21: Exec Sponsor | N21: =H21 | O21: =I21 | P21: =J21 | Q21: 2
B22: Product Knowledge | C22: SE | D22: L2 | H22: =IF(E22="L3 - Advanced",3,IF(E22="L2 - Proficient",2,IF(E22="L1 - Developing",1,""))) | I22: =IF(F22="L3 - Advanced",3,IF(F22="L2 - Proficient",2,IF(F22="L1 - Developing",1,""))) | J22: =IF(G22="L3 - Advanced",3,IF(G22="L2 - Proficient",2,IF(G22="L1 - Developing",1,""))) | M22: Product Know | N22: =H22 | O22: =I22 | P22: =J22 | Q22: 2
... B32: Software & Services Attach | C32: S | D32: L2 | H32: =IF(E32="L3 - Advanced",3,IF(E32="L2 - Proficient",2,IF(E32="L1 - Developing",1,""))) | I32: =IF(F32="L3 - Advanced",3,IF(F32="L2 - Proficient",2,IF(F32="L1 - Developing",1,""))) | J32: =IF(G32="L3 - Advanced",3,IF(G32="L2 - Proficient",2,IF(G32="L1 - Developing",1,""))) | M32: SW/Svc Attach | N32: =H32 | O32: =I32 | P32: =J32 | Q32: 2
B33: AVERAGE MATURITY SCORE | E33: =IFERROR(AVERAGE(H11:H32),"") | F33: =IFERROR(AVERAGE(I11:I32),"") | G33: =IFERROR(AVERAGE(J11:J32),"") | H33: =IFERROR(AVERAGE(H11:J32),"")

Sheet Oseid Mohamemed Faqih
B2: SE | D2: Schneider Electric
D3: APEX ASSESSMENT · AM05
B5: Account Manager: Account Manager 5 · Account: Account 5 · Zone: MEA · Track: Acquisition
B7: Account Manager | D7: Account Manager 5 | E7: Account Name | G7: Account 5 | H7: Zone | I7: MEA | J7: Track | K7: Acquisition
B8: Self Assessment Date: | E8: Manager Assessment Date: | H8: APEX Panel Date:
E9: ◀ SELF ASSESSMENT ▶ | F9: ◀ MANAGER ASSESSMENT ▶ | G9: ◀ APEX PANEL ASSESSMENT ▶
B10: Capability | C10: Src | D10: Req Lv | E10: SELF (L1/L2/L3) | F10: MANAGER (L1/L2/L3) | G10: APEX PANEL (L1/L2/L3) | H10: Self # | I10: Mgr # | J10: APEX # | K10: Notes / Evidence & Behavioural Observations | M10: Capability | N10: Self | O10: Manager | P10: APEX | Q10: Target
B11: Account Management | C11: SE | D11: L3 | H11: =IF(E11="L3 - Advanced",3,IF(E11="L2 - Proficient",2,IF(E11="L1 - Developing",1,""))) | I11: =IF(F11="L3 - Advanced",3,IF(F11="L2 - Proficient",2,IF(F11="L1 - Developing",1,""))) | J11: =IF(G11="L3 - Advanced",3,IF(G11="L2 - Proficient",2,IF(G11="L1 - Developing",1,""))) | M11: Acct Mgmt | N11: =H11 | O11: =I11 | P11: =J11 | Q11: 2
B12: Strategic Account Ambition | C12: C | D12: L2 | H12: =IF(E12="L3 - Advanced",3,IF(E12="L2 - Proficient",2,IF(E12="L1 - Developing",1,""))) | I12: =IF(F12="L3 - Advanced",3,IF(F12="L2 - Proficient",2,IF(F12="L1 - Developing",1,""))) | J12: =IF(G12="L3 - Advanced",3,IF(G12="L2 - Proficient",2,IF(G12="L1 - Developing",1,""))) | M12: Strat Ambition | N12: =H12 | O12: =I12 | P12: =J12 | Q12: 2
B13: Consultative Selling | C13: SE | D13: L2 | H13: =IF(E13="L3 - Advanced",3,IF(E13="L2 - Proficient",2,IF(E13="L1 - Developing",1,""))) | I13: =IF(F13="L3 - Advanced",3,IF(F13="L2 - Proficient",2,IF(F13="L1 - Developing",1,""))) | J13: =IF(G13="L3 - Advanced",3,IF(G13="L2 - Proficient",2,IF(G13="L1 - Developing",1,""))) | M13: Consultative | N13: =H13 | O13: =I13 | P13: =J13 | Q13: 2
B14: Negotiation | C14: SE | D14: L2 | H14: =IF(E14="L3 - Advanced",3,IF(E14="L2 - Proficient",2,IF(E14="L1 - Developing",1,""))) | I14: =IF(F14="L3 - Advanced",3,IF(F14="L2 - Proficient",2,IF(F14="L1 - Developing",1,""))) | J14: =IF(G14="L3 - Advanced",3,IF(G14="L2 - Proficient",2,IF(G14="L1 - Developing",1,""))) | M14: Negotiation | N14: =H14 | O14: =I14 | P14: =J14 | Q14: 2
B15: Value Creation / Business Case | C15: C | D15: L2 | H15: =IF(E15="L3 - Advanced",3,IF(E15="L2 - Proficient",2,IF(E15="L1 - Developing",1,""))) | I15: =IF(F15="L3 - Advanced",3,IF(F15="L2 - Proficient",2,IF(F15="L1 - Developing",1,""))) | J15: =IF(G15="L3 - Advanced",3,IF(G15="L2 - Proficient",2,IF(G15="L1 - Developing",1,""))) | M15: Value/BizCase | N15: =H15 | O15: =I15 | P15: =J15 | Q15: 2
B16: Customer Relationship Management | C16: SE | D16: L2 | H16: =IF(E16="L3 - Advanced",3,IF(E16="L2 - Proficient",2,IF(E16="L1 - Developing",1,""))) | I16: =IF(F16="L3 - Advanced",3,IF(F16="L2 - Proficient",2,IF(F16="L1 - Developing",1,""))) | J16: =IF(G16="L3 - Advanced",3,IF(G16="L2 - Proficient",2,IF(G16="L1 - Developing",1,""))) | M16: CRM | N16: =H16 | O16: =I16 | P16: =J16 | Q16: 2
B17: Stakeholder Management | C17: SE | D17: L2 | H17: =IF(E17="L3 - Advanced",3,IF(E17="L2 - Proficient",2,IF(E17="L1 - Developing",1,""))) | I17: =IF(F17="L3 - Advanced",3,IF(F17="L2 - Proficient",2,IF(F17="L1 - Developing",1,""))) | J17: =IF(G17="L3 - Advanced",3,IF(G17="L2 - Proficient",2,IF(G17="L1 - Developing",1,""))) | M17: Stakeholder | N17: =H17 | O17: =I17 | P17: =J17 | Q17: 2
B18: Influencing Skills | C18: SE | D18: L2 | H18: =IF(E18="L3 - Advanced",3,IF(E18="L2 - Proficient",2,IF(E18="L1 - Developing",1,""))) | I18: =IF(F18="L3 - Advanced",3,IF(F18="L2 - Proficient",2,IF(F18="L1 - Developing",1,""))) | J18: =IF(G18="L3 - Advanced",3,IF(G18="L2 - Proficient",2,IF(G18="L1 - Developing",1,""))) | M18: Influencing | N18: =H18 | O18: =I18 | P18: =J18 | Q18: 2
B19: Executive Presence | C19: C | D19: L2 | H19: =IF(E19="L3 - Advanced",3,IF(E19="L2 - Proficient",2,IF(E19="L1 - Developing",1,""))) | I19: =IF(F19="L3 - Advanced",3,IF(F19="L2 - Proficient",2,IF(F19="L1 - Developing",1,""))) | J19: =IF(G19="L3 - Advanced",3,IF(G19="L2 - Proficient",2,IF(G19="L1 - Developing",1,""))) | M19: Exec Presence | N19: =H19 | O19: =I19 | P19: =J19 | Q19: 2
B20: C-Level Engagement | C20: C | D20: L2 | H20: =IF(E20="L3 - Advanced",3,IF(E20="L2 - Proficient",2,IF(E20="L1 - Developing",1,""))) | I20: =IF(F20="L3 - Advanced",3,IF(F20="L2 - Proficient",2,IF(F20="L1 - Developing",1,""))) | J20: =IF(G20="L3 - Advanced",3,IF(G20="L2 - Proficient",2,IF(G20="L1 - Developing",1,""))) | M20: C-Level | N20: =H20 | O20: =I20 | P20: =J20 | Q20: 2
B21: Executive Sponsorship Mobilization | C21: C | D21: L2 | H21: =IF(E21="L3 - Advanced",3,IF(E21="L2 - Proficient",2,IF(E21="L1 - Developing",1,""))) | I21: =IF(F21="L3 - Advanced",3,IF(F21="L2 - Proficient",2,IF(F21="L1 - Developing",1,""))) | J21: =IF(G21="L3 - Advanced",3,IF(G21="L2 - Proficient",2,IF(G21="L1 - Developing",1,""))) | M21: Exec Sponsor | N21: =H21 | O21: =I21 | P21: =J21 | Q21: 2
B22: Product Knowledge | C22: SE | D22: L2 | H22: =IF(E22="L3 - Advanced",3,IF(E22="L2 - Proficient",2,IF(E22="L1 - Developing",1,""))) | I22: =IF(F22="L3 - Advanced",3,IF(F22="L2 - Proficient",2,IF(F22="L1 - Developing",1,""))) | J22: =IF(G22="L3 - Advanced",3,IF(G22="L2 - Proficient",2,IF(G22="L1 - Developing",1,""))) | M22: Product Know | N22: =H22 | O22: =I22 | P22: =J22 | Q22: 2
... B32: Software & Services Attach | C32: S | D32: L2 | H32: =IF(E32="L3 - Advanced",3,IF(E32="L2 - Proficient",2,IF(E32="L1 - Developing",1,""))) | I32: =IF(F32="L3 - Advanced",3,IF(F32="L2 - Proficient",2,IF(F32="L1 - Developing",1,""))) | J32: =IF(G32="L3 - Advanced",3,IF(G32="L2 - Proficient",2,IF(G32="L1 - Developing",1,""))) | M32: SW/Svc Attach | N32: =H32 | O32: =I32 | P32: =J32 | Q32: 2
B33: AVERAGE MATURITY SCORE | E33: =IFERROR(AVERAGE(H11:H32),"") | F33: =IFERROR(AVERAGE(I11:I32),"") | G33: =IFERROR(AVERAGE(J11:J32),"") | H33: =IFERROR(AVERAGE(H11:J32),"")

Sheet Kamel Bedrane
B2: SE | D2: Schneider Electric
D3: APEX ASSESSMENT · AM06
B5: Account Manager: Account Manager 6 · Account: Account 6 · Zone: MEA · Track: Acquisition
B7: Account Manager | D7: Account Manager 6 | E7: Account Name | G7: Account 6 | H7: Zone | I7: MEA | J7: Track | K7: Acquisition
B8: Self Assessment Date: | E8: Manager Assessment Date: | H8: APEX Panel Date:
E9: ◀ SELF ASSESSMENT ▶ | F9: ◀ MANAGER ASSESSMENT ▶ | G9: ◀ APEX PANEL ASSESSMENT ▶
B10: Capability | C10: Src | D10: Req Lv | E10: SELF (L1/L2/L3) | F10: MANAGER (L1/L2/L3) | G10: APEX PANEL (L1/L2/L3) | H10: Self # | I10: Mgr # | J10: APEX # | K10: Notes / Evidence & Behavioural Observations | M10: Capability | N10: Self | O10: Manager | P10: APEX | Q10: Target
B11: Account Management | C11: SE | D11: L3 | H11: =IF(E11="L3 - Advanced",3,IF(E11="L2 - Proficient",2,IF(E11="L1 - Developing",1,""))) | I11: =IF(F11="L3 - Advanced",3,IF(F11="L2 - Proficient",2,IF(F11="L1 - Developing",1,""))) | J11: =IF(G11="L3 - Advanced",3,IF(G11="L2 - Proficient",2,IF(G11="L1 - Developing",1,""))) | M11: Acct Mgmt | N11: =H11 | O11: =I11 | P11: =J11 | Q11: 2
B12: Strategic Account Ambition | C12: C | D12: L2 | H12: =IF(E12="L3 - Advanced",3,IF(E12="L2 - Proficient",2,IF(E12="L1 - Developing",1,""))) | I12: =IF(F12="L3 - Advanced",3,IF(F12="L2 - Proficient",2,IF(F12="L1 - Developing",1,""))) | J12: =IF(G12="L3 - Advanced",3,IF(G12="L2 - Proficient",2,IF(G12="L1 - Developing",1,""))) | M12: Strat Ambition | N12: =H12 | O12: =I12 | P12: =J12 | Q12: 2
B13: Consultative Selling | C13: SE | D13: L2 | H13: =IF(E13="L3 - Advanced",3,IF(E13="L2 - Proficient",2,IF(E13="L1 - Developing",1,""))) | I13: =IF(F13="L3 - Advanced",3,IF(F13="L2 - Proficient",2,IF(F13="L1 - Developing",1,""))) | J13: =IF(G13="L3 - Advanced",3,IF(G13="L2 - Proficient",2,IF(G13="L1 - Developing",1,""))) | M13: Consultative | N13: =H13 | O13: =I13 | P13: =J13 | Q13: 2
B14: Negotiation | C14: SE | D14: L2 | H14: =IF(E14="L3 - Advanced",3,IF(E14="L2 - Proficient",2,IF(E14="L1 - Developing",1,""))) | I14: =IF(F14="L3 - Advanced",3,IF(F14="L2 - Proficient",2,IF(F14="L1 - Developing",1,""))) | J14: =IF(G14="L3 - Advanced",3,IF(G14="L2 - Proficient",2,IF(G14="L1 - Developing",1,""))) | M14: Negotiation | N14: =H14 | O14: =I14 | P14: =J14 | Q14: 2
B15: Value Creation / Business Case | C15: C | D15: L2 | H15: =IF(E15="L3 - Advanced",3,IF(E15="L2 - Proficient",2,IF(E15="L1 - Developing",1,""))) | I15: =IF(F15="L3 - Advanced",3,IF(F15="L2 - Proficient",2,IF(F15="L1 - Developing",1,""))) | J15: =IF(G15="L3 - Advanced",3,IF(G15="L2 - Proficient",2,IF(G15="L1 - Developing",1,""))) | M15: Value/BizCase | N15: =H15 | O15: =I15 | P15: =J15 | Q15: 2
B16: Customer Relationship Management | C16: SE | D16: L2 | H16: =IF(E16="L3 - Advanced",3,IF(E16="L2 - Proficient",2,IF(E16="L1 - Developing",1,""))) | I16: =IF(F16="L3 - Advanced",3,IF(F16="L2 - Proficient",2,IF(F16="L1 - Developing",1,""))) | J16: =IF(G16="L3 - Advanced",3,IF(G16="L2 - Proficient",2,IF(G16="L1 - Developing",1,""))) | M16: CRM | N16: =H16 | O16: =I16 | P16: =J16 | Q16: 2
B17: Stakeholder Management | C17: SE | D17: L2 | H17: =IF(E17="L3 - Advanced",3,IF(E17="L2 - Proficient",2,IF(E17="L1 - Developing",1,""))) | I17: =IF(F17="L3 - Advanced",3,IF(F17="L2 - Proficient",2,IF(F17="L1 - Developing",1,""))) | J17: =IF(G17="L3 - Advanced",3,IF(G17="L2 - Proficient",2,IF(G17="L1 - Developing",1,""))) | M17: Stakeholder | N17: =H17 | O17: =I17 | P17: =J17 | Q17: 2
B18: Influencing Skills | C18: SE | D18: L2 | H18: =IF(E18="L3 - Advanced",3,IF(E18="L2 - Proficient",2,IF(E18="L1 - Developing",1,""))) | I18: =IF(F18="L3 - Advanced",3,IF(F18="L2 - Proficient",2,IF(F18="L1 - Developing",1,""))) | J18: =IF(G18="L3 - Advanced",3,IF(G18="L2 - Proficient",2,IF(G18="L1 - Developing",1,""))) | M18: Influencing | N18: =H18 | O18: =I18 | P18: =J18 | Q18: 2
B19: Executive Presence | C19: C | D19: L2 | H19: =IF(E19="L3 - Advanced",3,IF(E19="L2 - Proficient",2,IF(E19="L1 - Developing",1,""))) | I19: =IF(F19="L3 - Advanced",3,IF(F19="L2 - Proficient",2,IF(F19="L1 - Developing",1,""))) | J19: =IF(G19="L3 - Advanced",3,IF(G19="L2 - Proficient",2,IF(G19="L1 - Developing",1,""))) | M19: Exec Presence | N19: =H19 | O19: =I19 | P19: =J19 | Q19: 2
B20: C-Level Engagement | C20: C | D20: L2 | H20: =IF(E20="L3 - Advanced",3,IF(E20="L2 - Proficient",2,IF(E20="L1 - Developing",1,""))) | I20: =IF(F20="L3 - Advanced",3,IF(F20="L2 - Proficient",2,IF(F20="L1 - Developing",1,""))) | J20: =IF(G20="L3 - Advanced",3,IF(G20="L2 - Proficient",2,IF(G20="L1 - Developing",1,""))) | M20: C-Level | N20: =H20 | O20: =I20 | P20: =J20 | Q20: 2
B21: Executive Sponsorship Mobilization | C21: C | D21: L2 | H21: =IF(E21="L3 - Advanced",3,IF(E21="L2 - Proficient",2,IF(E21="L1 - Developing",1,""))) | I21: =IF(F21="L3 - Advanced",3,IF(F21="L2 - Proficient",2,IF(F21="L1 - Developing",1,""))) | J21: =IF(G21="L3 - Advanced",3,IF(G21="L2 - Proficient",2,IF(G21="L1 - Developing",1,""))) | M21: Exec Sponsor | N21: =H21 | O21: =I21 | P21: =J21 | Q21: 2
B22: Product Knowledge | C22: SE | D22: L2 | H22: =IF(E22="L3 - Advanced",3,IF(E22="L2 - Proficient",2,IF(E22="L1 - Developing",1,""))) | I22: =IF(F22="L3 - Advanced",3,IF(F22="L2 - Proficient",2,IF(F22="L1 - Developing",1,""))) | J22: =IF(G22="L3 - Advanced",3,IF(G22="L2 - Proficient",2,IF(G22="L1 - Developing",1,""))) | M22: Product Know | N22: =H22 | O22: =I22 | P22: =J22 | Q22: 2
... B32: Software & Services Attach | C32: S | D32: L2 | H32: =IF(E32="L3 - Advanced",3,IF(E32="L2 - Proficient",2,IF(E32="L1 - Developing",1,""))) | I32: =IF(F32="L3 - Advanced",3,IF(F32="L2 - Proficient",2,IF(F32="L1 - Developing",1,""))) | J32: =IF(G32="L3 - Advanced",3,IF(G32="L2 - Proficient",2,IF(G32="L1 - Developing",1,""))) | M32: SW/Svc Attach | N32: =H32 | O32: =I32 | P32: =J32 | Q32: 2
B33: AVERAGE MATURITY SCORE | E33: =IFERROR(AVERAGE(H11:H32),"") | F33: =IFERROR(AVERAGE(I11:I32),"") | G33: =IFERROR(AVERAGE(J11:J32),"") | H33: =IFERROR(AVERAGE(H11:J32),"")

Sheet Moamen Mohamed Ahmed Ibrahim
B2: SE | D2: Schneider Electric
D3: APEX ASSESSMENT · AM07
B5: Account Manager: Account Manager 7 · Account: Account 7 · Zone: SAM · Track: Saturation
B7: Account Manager | D7: Account Manager 7 | E7: Account Name | G7: Account 7 | H7: Zone | I7: MEA | J7: Track | K7: Saturation
B8: Self Assessment Date: | E8: Manager Assessment Date: | H8: APEX Panel Date:
E9: ◀ SELF ASSESSMENT ▶ | F9: ◀ MANAGER ASSESSMENT ▶ | G9: ◀ APEX PANEL ASSESSMENT ▶
B10: Capability | C10: Src | D10: Req Lv | E10: SELF (L1/L2/L3) | F10: MANAGER (L1/L2/L3) | G10: APEX PANEL (L1/L2/L3) | H10: Self # | I10: Mgr # | J10: APEX # | K10: Notes / Evidence & Behavioural Observations | M10: Capability | N10: Self | O10: Manager | P10: APEX | Q10: Target
B11: Account Management | C11: SE | D11: L3 | H11: =IF(E11="L3 - Advanced",3,IF(E11="L2 - Proficient",2,IF(E11="L1 - Developing",1,""))) | I11: =IF(F11="L3 - Advanced",3,IF(F11="L2 - Proficient",2,IF(F11="L1 - Developing",1,""))) | J11: =IF(G11="L3 - Advanced",3,IF(G11="L2 - Proficient",2,IF(G11="L1 - Developing",1,""))) | M11: Acct Mgmt | N11: =H11 | O11: =I11 | P11: =J11 | Q11: 2
B12: Strategic Account Ambition | C12: C | D12: L2 | H12: =IF(E12="L3 - Advanced",3,IF(E12="L2 - Proficient",2,IF(E12="L1 - Developing",1,""))) | I12: =IF(F12="L3 - Advanced",3,IF(F12="L2 - Proficient",2,IF(F12="L1 - Developing",1,""))) | J12: =IF(G12="L3 - Advanced",3,IF(G12="L2 - Proficient",2,IF(G12="L1 - Developing",1,""))) | M12: Strat Ambition | N12: =H12 | O12: =I12 | P12: =J12 | Q12: 2
B13: Consultative Selling | C13: SE | D13: L2 | H13: =IF(E13="L3 - Advanced",3,IF(E13="L2 - Proficient",2,IF(E13="L1 - Developing",1,""))) | I13: =IF(F13="L3 - Advanced",3,IF(F13="L2 - Proficient",2,IF(F13="L1 - Developing",1,""))) | J13: =IF(G13="L3 - Advanced",3,IF(G13="L2 - Proficient",2,IF(G13="L1 - Developing",1,""))) | M13: Consultative | N13: =H13 | O13: =I13 | P13: =J13 | Q13: 2
B14: Negotiation | C14: SE | D14: L2 | H14: =IF(E14="L3 - Advanced",3,IF(E14="L2 - Proficient",2,IF(E14="L1 - Developing",1,""))) | I14: =IF(F14="L3 - Advanced",3,IF(F14="L2 - Proficient",2,IF(F14="L1 - Developing",1,""))) | J14: =IF(G14="L3 - Advanced",3,IF(G14="L2 - Proficient",2,IF(G14="L1 - Developing",1,""))) | M14: Negotiation | N14: =H14 | O14: =I14 | P14: =J14 | Q14: 2
B15: Value Creation / Business Case | C15: C | D15: L2 | H15: =IF(E15="L3 - Advanced",3,IF(E15="L2 - Proficient",2,IF(E15="L1 - Developing",1,""))) | I15: =IF(F15="L3 - Advanced",3,IF(F15="L2 - Proficient",2,IF(F15="L1 - Developing",1,""))) | J15: =IF(G15="L3 - Advanced",3,IF(G15="L2 - Proficient",2,IF(G15="L1 - Developing",1,""))) | M15: Value/BizCase | N15: =H15 | O15: =I15 | P15: =J15 | Q15: 2
B16: Customer Relationship Management | C16: SE | D16: L2 | H16: =IF(E16="L3 - Advanced",3,IF(E16="L2 - Proficient",2,IF(E16="L1 - Developing",1,""))) | I16: =IF(F16="L3 - Advanced",3,IF(F16="L2 - Proficient",2,IF(F16="L1 - Developing",1,""))) | J16: =IF(G16="L3 - Advanced",3,IF(G16="L2 - Proficient",2,IF(G16="L1 - Developing",1,""))) | M16: CRM | N16: =H16 | O16: =I16 | P16: =J16 | Q16: 2
B17: Stakeholder Management | C17: SE | D17: L2 | H17: =IF(E17="L3 - Advanced",3,IF(E17="L2 - Proficient",2,IF(E17="L1 - Developing",1,""))) | I17: =IF(F17="L3 - Advanced",3,IF(F17="L2 - Proficient",2,IF(F17="L1 - Developing",1,""))) | J17: =IF(G17="L3 - Advanced",3,IF(G17="L2 - Proficient",2,IF(G17="L1 - Developing",1,""))) | M17: Stakeholder | N17: =H17 | O17: =I17 | P17: =J17 | Q17: 2
B18: Influencing Skills | C18: SE | D18: L2 | H18: =IF(E18="L3 - Advanced",3,IF(E18="L2 - Proficient",2,IF(E18="L1 - Developing",1,""))) | I18: =IF(F18="L3 - Advanced",3,IF(F18="L2 - Proficient",2,IF(F18="L1 - Developing",1,""))) | J18: =IF(G18="L3 - Advanced",3,IF(G18="L2 - Proficient",2,IF(G18="L1 - Developing",1,""))) | M18: Influencing | N18: =H18 | O18: =I18 | P18: =J18 | Q18: 2
B19: Executive Presence | C19: C | D19: L2 | H19: =IF(E19="L3 - Advanced",3,IF(E19="L2 - Proficient",2,IF(E19="L1 - Developing",1,""))) | I19: =IF(F19="L3 - Advanced",3,IF(F19="L2 - Proficient",2,IF(F19="L1 - Developing",1,""))) | J19: =IF(G19="L3 - Advanced",3,IF(G19="L2 - Proficient",2,IF(G19="L1 - Developing",1,""))) | M19: Exec Presence | N19: =H19 | O19: =I19 | P19: =J19 | Q19: 2
B20: C-Level Engagement | C20: C | D20: L2 | H20: =IF(E20="L3 - Advanced",3,IF(E20="L2 - Proficient",2,IF(E20="L1 - Developing",1,""))) | I20: =IF(F20="L3 - Advanced",3,IF(F20="L2 - Proficient",2,IF(F20="L1 - Developing",1,""))) | J20: =IF(G20="L3 - Advanced",3,IF(G20="L2 - Proficient",2,IF(G20="L1 - Developing",1,""))) | M20: C-Level | N20: =H20 | O20: =I20 | P20: =J20 | Q20: 2
B21: Executive Sponsorship Mobilization | C21: C | D21: L2 | H21: =IF(E21="L3 - Advanced",3,IF(E21="L2 - Proficient",2,IF(E21="L1 - Developing",1,""))) | I21: =IF(F21="L3 - Advanced",3,IF(F21="L2 - Proficient",2,IF(F21="L1 - Developing",1,""))) | J21: =IF(G21="L3 - Advanced",3,IF(G21="L2 - Proficient",2,IF(G21="L1 - Developing",1,""))) | M21: Exec Sponsor | N21: =H21 | O21: =I21 | P21: =J21 | Q21: 2
B22: Product Knowledge | C22: SE | D22: L2 | H22: =IF(E22="L3 - Advanced",3,IF(E22="L2 - Proficient",2,IF(E22="L1 - Developing",1,""))) | I22: =IF(F22="L3 - Advanced",3,IF(F22="L2 - Proficient",2,IF(F22="L1 - Developing",1,""))) | J22: =IF(G22="L3 - Advanced",3,IF(G22="L2 - Proficient",2,IF(G22="L1 - Developing",1,""))) | M22: Product Know | N22: =H22 | O22: =I22 | P22: =J22 | Q22: 2
... B32: Software & Services Attach | C32: S | D32: L2 | H32: =IF(E32="L3 - Advanced",3,IF(E32="L2 - Proficient",2,IF(E32="L1 - Developing",1,""))) | I32: =IF(F32="L3 - Advanced",3,IF(F32="L2 - Proficient",2,IF(F32="L1 - Developing",1,""))) | J32: =IF(G32="L3 - Advanced",3,IF(G32="L2 - Proficient",2,IF(G32="L1 - Developing",1,""))) | M32: SW/Svc Attach | N32: =H32 | O32: =I32 | P32: =J32 | Q32: 2
B33: AVERAGE MATURITY SCORE | E33: =IFERROR(AVERAGE(H11:H32),"") | F33: =IFERROR(AVERAGE(I11:I32),"") | G33: =IFERROR(AVERAGE(J11:J32),"") | H33: =IFERROR(AVERAGE(H11:J32),"")

Sheet Ahmed Abdel-Maugod
B2: SE | D2: Schneider Electric
D3: APEX ASSESSMENT · AM08
B5: Account Manager: Account Manager 8 · Account: Account 8 · Zone: SAM · Track: Acquisition
B7: Account Manager | D7: Account Manager 8 | E7: Account Name | G7: Account 8 | H7: Zone | I7: MEA | J7: Track | K7: Acquisition
B8: Self Assessment Date: | E8: Manager Assessment Date: | H8: APEX Panel Date:
E9: ◀ SELF ASSESSMENT ▶ | F9: ◀ MANAGER ASSESSMENT ▶ | G9: ◀ APEX PANEL ASSESSMENT ▶
B10: Capability | C10: Src | D10: Req Lv | E10: SELF (L1/L2/L3) | F10: MANAGER (L1/L2/L3) | G10: APEX PANEL (L1/L2/L3) | H10: Self # | I10: Mgr # | J10: APEX # | K10: Notes / Evidence & Behavioural Observations | M10: Capability | N10: Self | O10: Manager | P10: APEX | Q10: Target
B11: Account Management | C11: SE | D11: L3 | H11: =IF(E11="L3 - Advanced",3,IF(E11="L2 - Proficient",2,IF(E11="L1 - Developing",1,""))) | I11: =IF(F11="L3 - Advanced",3,IF(F11="L2 - Proficient",2,IF(F11="L1 - Developing",1,""))) | J11: =IF(G11="L3 - Advanced",3,IF(G11="L2 - Proficient",2,IF(G11="L1 - Developing",1,""))) | M11: Acct Mgmt | N11: =H11 | O11: =I11 | P11: =J11 | Q11: 2
B12: Strategic Account Ambition | C12: C | D12: L2 | H12: =IF(E12="L3 - Advanced",3,IF(E12="L2 - Proficient",2,IF(E12="L1 - Developing",1,""))) | I12: =IF(F12="L3 - Advanced",3,IF(F12="L2 - Proficient",2,IF(F12="L1 - Developing",1,""))) | J12: =IF(G12="L3 - Advanced",3,IF(G12="L2 - Proficient",2,IF(G12="L1 - Developing",1,""))) | M12: Strat Ambition | N12: =H12 | O12: =I12 | P12: =J12 | Q12: 2
B13: Consultative Selling | C13: SE | D13: L2 | H13: =IF(E13="L3 - Advanced",3,IF(E13="L2 - Proficient",2,IF(E13="L1 - Developing",1,""))) | I13: =IF(F13="L3 - Advanced",3,IF(F13="L2 - Proficient",2,IF(F13="L1 - Developing",1,""))) | J13: =IF(G13="L3 - Advanced",3,IF(G13="L2 - Proficient",2,IF(G13="L1 - Developing",1,""))) | M13: Consultative | N13: =H13 | O13: =I13 | P13: =J13 | Q13: 2
B14: Negotiation | C14: SE | D14: L2 | H14: =IF(E14="L3 - Advanced",3,IF(E14="L2 - Proficient",2,IF(E14="L1 - Developing",1,""))) | I14: =IF(F14="L3 - Advanced",3,IF(F14="L2 - Proficient",2,IF(F14="L1 - Developing",1,""))) | J14: =IF(G14="L3 - Advanced",3,IF(G14="L2 - Proficient",2,IF(G14="L1 - Developing",1,""))) | M14: Negotiation | N14: =H14 | O14: =I14 | P14: =J14 | Q14: 2
B15: Value Creation / Business Case | C15: C | D15: L2 | H15: =IF(E15="L3 - Advanced",3,IF(E15="L2 - Proficient",2,IF(E15="L1 - Developing",1,""))) | I15: =IF(F15="L3 - Advanced",3,IF(F15="L2 - Proficient",2,IF(F15="L1 - Developing",1,""))) | J15: =IF(G15="L3 - Advanced",3,IF(G15="L2 - Proficient",2,IF(G15="L1 - Developing",1,""))) | M15: Value/BizCase | N15: =H15 | O15: =I15 | P15: =J15 | Q15: 2
B16: Customer Relationship Management | C16: SE | D16: L2 | H16: =IF(E16="L3 - Advanced",3,IF(E16="L2 - Proficient",2,IF(E16="L1 - Developing",1,""))) | I16: =IF(F16="L3 - Advanced",3,IF(F16="L2 - Proficient",2,IF(F16="L1 - Developing",1,""))) | J16: =IF(G16="L3 - Advanced",3,IF(G16="L2 - Proficient",2,IF(G16="L1 - Developing",1,""))) | M16: CRM | N16: =H16 | O16: =I16 | P16: =J16 | Q16: 2
B17: Stakeholder Management | C17: SE | D17: L2 | H17: =IF(E17="L3 - Advanced",3,IF(E17="L2 - Proficient",2,IF(E17="L1 - Developing",1,""))) | I17: =IF(F17="L3 - Advanced",3,IF(F17="L2 - Proficient",2,IF(F17="L1 - Developing",1,""))) | J17: =IF(G17="L3 - Advanced",3,IF(G17="L2 - Proficient",2,IF(G17="L1 - Developing",1,""))) | M17: Stakeholder | N17: =H17 | O17: =I17 | P17: =J17 | Q17: 2
B18: Influencing Skills | C18: SE | D18: L2 | H18: =IF(E18="L3 - Advanced",3,IF(E18="L2 - Proficient",2,IF(E18="L1 - Developing",1,""))) | I18: =IF(F18="L3 - Advanced",3,IF(F18="L2 - Proficient",2,IF(F18="L1 - Developing",1,""))) | J18: =IF(G18="L3 - Advanced",3,IF(G18="L2 - Proficient",2,IF(G18="L1 - Developing",1,""))) | M18: Influencing | N18: =H18 | O18: =I18 | P18: =J18 | Q18: 2
B19: Executive Presence | C19: C | D19: L2 | H19: =IF(E19="L3 - Advanced",3,IF(E19="L2 - Proficient",2,IF(E19="L1 - Developing",1,""))) | I19: =IF(F19="L3 - Advanced",3,IF(F19="L2 - Proficient",2,IF(F19="L1 - Developing",1,""))) | J19: =IF(G19="L3 - Advanced",3,IF(G19="L2 - Proficient",2,IF(G19="L1 - Developing",1,""))) | M19: Exec Presence | N19: =H19 | O19: =I19 | P19: =J19 | Q19: 2
B20: C-Level Engagement | C20: C | D20: L2 | H20: =IF(E20="L3 - Advanced",3,IF(E20="L2 - Proficient",2,IF(E20="L1 - Developing",1,""))) | I20: =IF(F20="L3 - Advanced",3,IF(F20="L2 - Proficient",2,IF(F20="L1 - Developing",1,""))) | J20: =IF(G20="L3 - Advanced",3,IF(G20="L2 - Proficient",2,IF(G20="L1 - Developing",1,""))) | M20: C-Level | N20: =H20 | O20: =I20 | P20: =J20 | Q20: 2
B21: Executive Sponsorship Mobilization | C21: C | D21: L2 | H21: =IF(E21="L3 - Advanced",3,IF(E21="L2 - Proficient",2,IF(E21="L1 - Developing",1,""))) | I21: =IF(F21="L3 - Advanced",3,IF(F21="L2 - Proficient",2,IF(F21="L1 - Developing",1,""))) | J21: =IF(G21="L3 - Advanced",3,IF(G21="L2 - Proficient",2,IF(G21="L1 - Developing",1,""))) | M21: Exec Sponsor | N21: =H21 | O21: =I21 | P21: =J21 | Q21: 2
B22: Product Knowledge | C22: SE | D22: L2 | H22: =IF(E22="L3 - Advanced",3,IF(E22="L2 - Proficient",2,IF(E22="L1 - Developing",1,""))) | I22: =IF(F22="L3 - Advanced",3,IF(F22="L2 - Proficient",2,IF(F22="L1 - Developing",1,""))) | J22: =IF(G22="L3 - Advanced",3,IF(G22="L2 - Proficient",2,IF(G22="L1 - Developing",1,""))) | M22: Product Know | N22: =H22 | O22: =I22 | P22: =J22 | Q22: 2
... B32: Software & Services Attach | C32: S | D32: L2 | H32: =IF(E32="L3 - Advanced",3,IF(E32="L2 - Proficient",2,IF(E32="L1 - Developing",1,""))) | I32: =IF(F32="L3 - Advanced",3,IF(F32="L2 - Proficient",2,IF(F32="L1 - Developing",1,""))) | J32: =IF(G32="L3 - Advanced",3,IF(G32="L2 - Proficient",2,IF(G32="L1 - Developing",1,""))) | M32: SW/Svc Attach | N32: =H32 | O32: =I32 | P32: =J32 | Q32: 2
B33: AVERAGE MATURITY SCORE | E33: =IFERROR(AVERAGE(H11:H32),"") | F33: =IFERROR(AVERAGE(I11:I32),"") | G33: =IFERROR(AVERAGE(J11:J32),"") | H33: =IFERROR(AVERAGE(H11:J32),"")

Sheet Moteeb Albaqami
B2: SE | D2: Schneider Electric
D3: APEX ASSESSMENT · AM09
B5: Account Manager: Account Manager 9 · Account: Account 9 · Zone: SAM · Track: Saturation
B7: Account Manager | D7: Account Manager 9 | E7: Account Name | G7: Account 9 | H7: Zone | I7: MEA | J7: Track | K7: Saturation
B8: Self Assessment Date: | E8: Manager Assessment Date: | H8: APEX Panel Date:
E9: ◀ SELF ASSESSMENT ▶ | F9: ◀ MANAGER ASSESSMENT ▶ | G9: ◀ APEX PANEL ASSESSMENT ▶
B10: Capability | C10: Src | D10: Req Lv | E10: SELF (L1/L2/L3) | F10: MANAGER (L1/L2/L3) | G10: APEX PANEL (L1/L2/L3) | H10: Self # | I10: Mgr # | J10: APEX # | K10: Notes / Evidence & Behavioural Observations | M10: Capability | N10: Self | O10: Manager | P10: APEX | Q10: Target
B11: Account Management | C11: SE | D11: L3 | H11: =IF(E11="L3 - Advanced",3,IF(E11="L2 - Proficient",2,IF(E11="L1 - Developing",1,""))) | I11: =IF(F11="L3 - Advanced",3,IF(F11="L2 - Proficient",2,IF(F11="L1 - Developing",1,""))) | J11: =IF(G11="L3 - Advanced",3,IF(G11="L2 - Proficient",2,IF(G11="L1 - Developing",1,""))) | M11: Acct Mgmt | N11: =H11 | O11: =I11 | P11: =J11 | Q11: 2
B12: Strategic Account Ambition | C12: C | D12: L2 | H12: =IF(E12="L3 - Advanced",3,IF(E12="L2 - Proficient",2,IF(E12="L1 - Developing",1,""))) | I12: =IF(F12="L3 - Advanced",3,IF(F12="L2 - Proficient",2,IF(F12="L1 - Developing",1,""))) | J12: =IF(G12="L3 - Advanced",3,IF(G12="L2 - Proficient",2,IF(G12="L1 - Developing",1,""))) | M12: Strat Ambition | N12: =H12 | O12: =I12 | P12: =J12 | Q12: 2
B13: Consultative Selling | C13: SE | D13: L2 | H13: =IF(E13="L3 - Advanced",3,IF(E13="L2 - Proficient",2,IF(E13="L1 - Developing",1,""))) | I13: =IF(F13="L3 - Advanced",3,IF(F13="L2 - Proficient",2,IF(F13="L1 - Developing",1,""))) | J13: =IF(G13="L3 - Advanced",3,IF(G13="L2 - Proficient",2,IF(G13="L1 - Developing",1,""))) | M13: Consultative | N13: =H13 | O13: =I13 | P13: =J13 | Q13: 2
B14: Negotiation | C14: SE | D14: L2 | H14: =IF(E14="L3 - Advanced",3,IF(E14="L2 - Proficient",2,IF(E14="L1 - Developing",1,""))) | I14: =IF(F14="L3 - Advanced",3,IF(F14="L2 - Proficient",2,IF(F14="L1 - Developing",1,""))) | J14: =IF(G14="L3 - Advanced",3,IF(G14="L2 - Proficient",2,IF(G14="L1 - Developing",1,""))) | M14: Negotiation | N14: =H14 | O14: =I14 | P14: =J14 | Q14: 2
B15: Value Creation / Business Case | C15: C | D15: L2 | H15: =IF(E15="L3 - Advanced",3,IF(E15="L2 - Proficient",2,IF(E15="L1 - Developing",1,""))) | I15: =IF(F15="L3 - Advanced",3,IF(F15="L2 - Proficient",2,IF(F15="L1 - Developing",1,""))) | J15: =IF(G15="L3 - Advanced",3,IF(G15="L2 - Proficient",2,IF(G15="L1 - Developing",1,""))) | M15: Value/BizCase | N15: =H15 | O15: =I15 | P15: =J15 | Q15: 2
B16: Customer Relationship Management | C16: SE | D16: L2 | H16: =IF(E16="L3 - Advanced",3,IF(E16="L2 - Proficient",2,IF(E16="L1 - Developing",1,""))) | I16: =IF(F16="L3 - Advanced",3,IF(F16="L2 - Proficient",2,IF(F16="L1 - Developing",1,""))) | J16: =IF(G16="L3 - Advanced",3,IF(G16="L2 - Proficient",2,IF(G16="L1 - Developing",1,""))) | M16: CRM | N16: =H16 | O16: =I16 | P16: =J16 | Q16: 2
B17: Stakeholder Management | C17: SE | D17: L2 | H17: =IF(E17="L3 - Advanced",3,IF(E17="L2 - Proficient",2,IF(E17="L1 - Developing",1,""))) | I17: =IF(F17="L3 - Advanced",3,IF(F17="L2 - Proficient",2,IF(F17="L1 - Developing",1,""))) | J17: =IF(G17="L3 - Advanced",3,IF(G17="L2 - Proficient",2,IF(G17="L1 - Developing",1,""))) | M17: Stakeholder | N17: =H17 | O17: =I17 | P17: =J17 | Q17: 2
B18: Influencing Skills | C18: SE | D18: L2 | H18: =IF(E18="L3 - Advanced",3,IF(E18="L2 - Proficient",2,IF(E18="L1 - Developing",1,""))) | I18: =IF(F18="L3 - Advanced",3,IF(F18="L2 - Proficient",2,IF(F18="L1 - Developing",1,""))) | J18: =IF(G18="L3 - Advanced",3,IF(G18="L2 - Proficient",2,IF(G18="L1 - Developing",1,""))) | M18: Influencing | N18: =H18 | O18: =I18 | P18: =J18 | Q18: 2
B19: Executive Presence | C19: C | D19: L2 | H19: =IF(E19="L3 - Advanced",3,IF(E19="L2 - Proficient",2,IF(E19="L1 - Developing",1,""))) | I19: =IF(F19="L3 - Advanced",3,IF(F19="L2 - Proficient",2,IF(F19="L1 - Developing",1,""))) | J19: =IF(G19="L3 - Advanced",3,IF(G19="L2 - Proficient",2,IF(G19="L1 - Developing",1,""))) | M19: Exec Presence | N19: =H19 | O19: =I19 | P19: =J19 | Q19: 2
B20: C-Level Engagement | C20: C | D20: L2 | H20: =IF(E20="L3 - Advanced",3,IF(E20="L2 - Proficient",2,IF(E20="L1 - Developing",1,""))) | I20: =IF(F20="L3 - Advanced",3,IF(F20="L2 - Proficient",2,IF(F20="L1 - Developing",1,""))) | J20: =IF(G20="L3 - Advanced",3,IF(G20="L2 - Proficient",2,IF(G20="L1 - Developing",1,""))) | M20: C-Level | N20: =H20 | O20: =I20 | P20: =J20 | Q20: 2
B21: Executive Sponsorship Mobilization | C21: C | D21: L2 | H21: =IF(E21="L3 - Advanced",3,IF(E21="L2 - Proficient",2,IF(E21="L1 - Developing",1,""))) | I21: =IF(F21="L3 - Advanced",3,IF(F21="L2 - Proficient",2,IF(F21="L1 - Developing",1,""))) | J21: =IF(G21="L3 - Advanced",3,IF(G21="L2 - Proficient",2,IF(G21="L1 - Developing",1,""))) | M21: Exec Sponsor | N21: =H21 | O21: =I21 | P21: =J21 | Q21: 2
B22: Product Knowledge | C22: SE | D22: L2 | H22: =IF(E22="L3 - Advanced",3,IF(E22="L2 - Proficient",2,IF(E22="L1 - Developing",1,""))) | I22: =IF(F22="L3 - Advanced",3,IF(F22="L2 - Proficient",2,IF(F22="L1 - Developing",1,""))) | J22: =IF(G22="L3 - Advanced",3,IF(G22="L2 - Proficient",2,IF(G22="L1 - Developing",1,""))) | M22: Product Know | N22: =H22 | O22: =I22 | P22: =J22 | Q22: 2
